Workbook

Sheet Standardised Data
B2: Calgro M3 — Statement of Financial Position | I2: Notes | M2: Key ratios | P2: ev | Q2: market cap | R2: total debt | S2: share capital | T2: minority interest | U2: cash and cash equivalents
C3: 2026 | D3: % change | E3: 2025 | F3: %change | G3: 2024 | H3: Trend/Average change | M3: EV/ EBITDA | N3: =P3/Q5 -> 11.792209 | P3: =SUM(Q3:T3) - U3 -> 2448074030 | Q3: 480480000 | R3: =C44 -> 2119679186 | S3: =C25 -> 28389249 | T3: =C29 -> 3248556 | U3: =C17 -> 183722961
B4: Non-current assets | P4: ebitda | Q4: operating income | R4: depreciatoon | S4: tax
B5: Construction contracts | C5: 2107206825 | D5: =(C5-E5)/E5 -> 0.26309904 | E5: 1668283132 | F5: =(E5-G5)/G5 -> 0.23085588 | G5: 1355384620 | H5: =(D5+F5)/2 -> 0.24697746 | Q5: =C60-C54 -> 207600966
B6: Loans to joint ventures | C6: 387466009 | D6: =(C6-E6)/E6 -> -0.18142833 | E6: 473344024 | F6: =(E6-G6)/G6 -> 0.17623711 | G6: 402422283 | H6: =(D6+F6)/2 -> -0.0025956081
B7: Investment in joint ventures | C7: 148981026 | D7: =(C7-E7)/E7 -> 0.090556819 | E7: 136610054 | F7: =(E7-G7)/G7 -> 0.99952527 | G7: 68321244 | H7: =(D7+F7)/2 -> 0.54504105
B8: Inventories | C8: 456368002 | D8: =(C8-E8)/E8 -> -0.12163955 | E8: 519568023 | F8: =(E8-G8)/G8 -> 0.032147891 | G8: 503385249 | H8: =(D8+F8)/2 -> -0.04474583 | M8: VALUATION
B9: Investments | C9: 20669356 | D9: =(C9-E9)/E9 -> 0.076726919 | E9: 19196470 | F9: =(E9-G9)/G9 -> 0.14472436 | G9: 16769513 | H9: =(D9+F9)/2 -> 0.11072564 | M9: Metric | N9: FY2026 | O9: FY2025 | P9: FY2024
B10: Property, plant and equipment | C10: 22798883 | D10: =(C10-E10)/E10 -> -0.12126498 | E10: 25945117 | F10: =(E10-G10)/G10 -> -0.11112385 | G10: 29188675 | H10: =(D10+F10)/2 -> -0.11619441 | M10: EV (R) | N10: =P3 -> 2448074030 | O10: — | P10: —
B11: Investment property | C11: 32497786 | D11: =(C11-E11)/E11 -> 0.44480267 | E11: 22492889 | F11: =(E11-G11)/G11 -> 0.015613698 | G11: 22147091 | H11: =(D11+F11)/2 -> 0.23020818 | M11: Market Cap (R) | N11: 411000000 | O11: — | P11: —
B12: Intangible assets | C12: 159650517 | D12: =(C12-E12)/E12 -> 0 | E12: 159650517 | F12: =(E12-G12)/G12 -> -1.0648258e-07 | G12: 159650534 | H12: =(D12+F12)/2 -> -5.3241288e-08 | M12: EV/EBITDA (x) | N12: 11.79x | O12: — | P12: —
B13: Deferred tax asset | C13: 10128435 | D13: =(C13-E13)/E13 -> -0.10865 | E13: 11363028 | F13: =(E13-G13)/G13 -> -0.2753866 | G13: 15681504 | H13: =(D13+F13)/2 -> -0.1920183 | M13: P/E Ratio (x) | N13: 2.57x | O13: 2.50x | P13: 2.25x
B14: Total non-current assets | C14: 2889398837 | D14: =(C14-E14)/E14 -> 1.0757733 | E14: 1391962650 | F14: =(E14-G14)/G14 -> 0.20170124 | G14: 1158326713 | H14: =(D14+F14)/2 -> 0.63873725 | M14: EPS Basic (cents) | N14: 167.4c | O14: 171.7c | P14: 191.1c
M15: PROFITABILITY
B16: Current assets | M16: Metric | N16: FY2026 | O16: FY2025 | P16: FY2024 | Q16: Trend
B17: Cash and cash equivalents | C17: 183722961 | D17: =(C17-E17)/E17 -> 0.18743505 | E17: 154722535 | F17: =(E17-G17)/G17 -> 0.26161963 | G17: 122638021 | H17: =(D17+F17)/2 -> 0.22452734 | M17: Revenue (R) | N17: 893174205 | O17: 868906517 | P17: 1290864982 | Q17: Bottoming
B18: Trade and other receivables | C18: 159624687 | D18: =(C18-E18)/E18 -> 0.93008636 | E18: 82703391 | F18: =(E18-G18)/G18 -> -0.41098544 | G18: 140409757 | H18: =(D18+F18)/2 -> 0.25955046 | M18: Revenue Growth | N18: 0.028 | O18: -0.327 | P18: — | Q18: Stabilising
B19: Current income tax assets | C19: 1743347 | D19: =(C19-E19)/E19 -> 5.0382555 | E19: 288717 | F19: =(E19-G19)/G19 -> 0.36028778 | G19: 212247 | H19: =(D19+F19)/2 -> 2.6992716 | M19: Gross Profit (R) | N19: 242913300 | O19: 255720011 | P19: 351316861 | Q19: Declining
B20: Total current assets | C20: 801458997 | D20: =(C20-E20)/E20 -> -0.5741915 | E20: 1882205247 | F20: =(E20-G20)/G20 -> 0.12177315 | G20: 1677884025 | H20: =(D20+F20)/2 -> -0.22620917 | M20: Gross Margin | N20: 0.272 | O20: 0.294 | P20: 0.272 | Q20: Stable
M21: Operating Profit (R) | N21: 171049317 | O21: 165720201 | P21: 259056503 | Q21: Declining
B22: Total assets | C22: 3690857834 | D22: =(C22-E22)/E22 -> 0.1272659 | E22: 3274167897 | F22: =(E22-G22)/G22 -> 0.1544163 | G22: 2836210738 | H22: =(D22+F22)/2 -> 0.1408411 | M22: Operating Margin | N22: 0.191 | O22: 0.191 | P22: 0.201 | Q22: Stable
M23: Net Profit (R) | N23: 160230003 | O23: 166115884 | P23: 195865219 | Q23: Declining
B24: Equity | M24: Net Margin | N24: 0.179 | O24: 0.191 | P24: 0.152 | Q24: Stable
B25: Stated capital | C25: 28389249 | D25: =(C25-E25)/E25 -> -0.16279725 | E25: 33909646 | F25: =(E25-G25)/G25 -> 0.072747327 | G25: 31610096 | H25: =(D25+F25)/2 -> -0.04502496 | M25: EBITDA (R) | N25: 207600966 | O25: — | P25: — | Q25: —
B26: Share-based payment reserve | C26: -1540004 | D26: =(C26-E26)/E26 -> -4.1707093 | E26: 485697 | F26: =(E26-G26)/G26 -> 0.33744823 | G26: 363152 | H26: =(D26+F26)/2 -> -1.9166305 | M26: LEVERAGE
B27: Retained income | C27: 1541080847 | D27: =(C27-E27)/E27 -> 0.10390489 | E27: 1396026833 | F27: =(E27-G27)/G27 -> 0.12411241 | G27: 1241892552 | H27: =(D27+F27)/2 -> 0.11400865 | M27: Metric | N27: FY2026 | O27: FY2025 | P27: FY2024 | Q27: Trend
B28: Equity attributable to owners | C28: 1567930092 | D28: =(C28-E28)/E28 -> 0.096131001 | E28: 1430422176 | F28: =(E28-G28)/G28 -> 0.12289864 | G28: 1273865800 | H28: =(D28+F28)/2 -> 0.10951482 | M28: Non-Current Borrowings (R) | N28: 1247291293 | O28: 965722194 | P28: 934796142 | Q28: Rising
B29: Non-controlling interests | C29: 3248556 | D29: =(C29-E29)/E29 -> -0.0015370869 | E29: 3253557 | F29: =(E29-G29)/G29 -> 3.8875985 | G29: 665676 | H29: =(D29+F29)/2 -> 1.9430307 | M29: Current Borrowings (R) | N29: 133000000 | O29: 140000000 | P29: — | Q29: Stable
B30: Total equity | C30: 1571178648 | D30: =(C30-E30)/E30 -> 0.095909355 | E30: 1433675733 | F30: =(E30-G30)/G30 -> 0.12486491 | G30: 1274531476 | H30: =(D30+F30)/2 -> 0.11038713 | M30: Total Debt (R) | N30: 1380291293 | O30: 1105722194 | P30: — | Q30: Rising
M31: Cash (R) | N31: 183722961 | O31: 154722535 | P31: 122638021 | Q31: Rising
B32: Non-current liabilities | M32: Net Debt (R) | N32: 1196568332 | O32: 951000000 | P32: — | Q32: Rising
B33: Borrowings (non-current) | C33: 1247291293 | D33: =(C33-E33)/E33 -> 0.29156325 | E33: 965722194 | F33: =(E33-G33)/G33 -> 0.033083205 | G33: 934796142 | H33: =(D33+F33)/2 -> 0.16232323 | M33: Net Debt/EBITDA (x) | N33: 5.77x | O33: — | P33: — | Q33: Elevated
B34: Deferred tax liability | C34: 409486025 | D34: =(C34-E34)/E34 -> 0.11861137 | E34: 366066389 | F34: =(E34-G34)/G34 -> 0.12284384 | G34: 326017186 | H34: =(D34+F34)/2 -> 0.12072761 | M34: Debt/Equity (x) | N34: 0.88x | O34: 0.77x | P34: — | Q34: Rising
B35: Maintenance provision | C35: 66328209 | D35: =(C35-E35)/E35 -> 0.14913327 | E35: 57720206 | G35: — | H35: =(D35+F35)/2 -> 0.074566634 | M35: Total Equity (R) | N35: 1571178648 | O35: 1433675733 | P35: 1274531476 | Q35: Growing
B36: Total non-current liabilities | C36: 1723105527 | D36: =(C36-E36)/E36 -> 0.2400825 | E36: 1389508789 | F36: =(E36-G36)/G36 -> 0.10207337 | G36: 1260813328 | H36: =(D36+F36)/2 -> 0.17107793 | M36: LIQUIDITY
M37: Metric | N37: FY2026 | O37: FY2025 | P37: FY2024 | Q37: Trend
B38: Current liabilities | M38: Current Assets (R) | N38: 801458997 | O38: 1882205247 | P38: 1677884025 | Q38: Declining
B39: Trade and other payables | C39: 263334249 | E39: 310925099 | F39: =(E39-G39)/G39 -> 0.035433928 | G39: 300284828 | H39: =(D39+F39)/2 -> 0.017716964 | M39: Current Liabilities (R) | N39: 396573659 | O39: 450983375 | P39: 300865934 | Q39: Declining
B40: Current income tax liabilities | C40: 239410 | D40: =(C40-E40)/E40 -> 3.1082092 | E40: 58276 | F40: =(E40-G40)/G40 -> -0.89971537 | G40: 581106 | H40: =(D40+F40)/2 -> 1.1042469 | M40: Current Ratio (x) | N40: 2.02x | O40: 4.17x | P40: 5.58x | Q40: Declining
B41: Current portion of borrowings | C41: 133000000 | D41: =(C41-E41)/E41 -> -0.05 | E41: 140000000 | G41: — | H41: =(D41+F41)/2 -> -0.025 | M41: Quick Ratio (x) | N41: 0.87x | O41: — | P41: — | Q41: Below 1x
...

Sheet Cumulative - Outlay
B1: Cumaltive 10year CGR Outlay
B3: Project | D3: 2026 | E3: 2027 | F3: 2028 | G3: 2029 | H3: 2030 | I3: 2031 | J3: 2032 | K3: 2033 | L3: 2034 | M3: 2035
B4: Bankenveld | C4: Inflow | D4: ='Bankenveld - Outlay'!C41 -> 0 | E4: ='Bankenveld - Outlay'!D41 -> 0 | F4: ='Bankenveld - Outlay'!E41 -> 768000 | G4: ='Bankenveld - Outlay'!F41 -> 1152000 | H4: ='Bankenveld - Outlay'!G41 -> 1536000 | I4: ='Bankenveld - Outlay'!H41 -> 1728000 | J4: ='Bankenveld - Outlay'!I41 -> 2304000 | K4: ='Bankenveld - Outlay'!J41 -> 2496000 | ... M4: ='Bankenveld - Outlay'!L41 -> 1920000
C5: Outflow | D5: ='Bankenveld - Outlay'!C40 -> -145000 | E5: ='Bankenveld - Outlay'!D40 -> -80000 | F5: ='Bankenveld - Outlay'!E40 -> -699846.4 | G5: ='Bankenveld - Outlay'!F40 -> -1029769.6 | H5: ='Bankenveld - Outlay'!G40 -> -1361692.8 | I5: ='Bankenveld - Outlay'!H40 -> -1526654.4 | J5: ='Bankenveld - Outlay'!I40 -> -2027539.2 | K5: ='Bankenveld - Outlay'!J40 -> -2193500.8 | ... M5: ='Bankenveld - Outlay'!L40 -> -1689616
B7: Memorial Parks | C7: Inflow | D7: ='Memorial Parks - Outlay'!C33 -> 105000 | E7: ='Memorial Parks - Outlay'!D33 -> 117000 | F7: ='Memorial Parks - Outlay'!E33 -> 127500 | G7: ='Memorial Parks - Outlay'!F33 -> 135000 | H7: ='Memorial Parks - Outlay'!G33 -> 142500 | I7: ='Memorial Parks - Outlay'!H33 -> 150000 | J7: ='Memorial Parks - Outlay'!I33 -> 150000 | K7: ='Memorial Parks - Outlay'!J33 -> 150000 | ... M7: ='Memorial Parks - Outlay'!L33 -> 150000 | P7: Make the bar graphs show which portion belongs to which for the cumlative graph
C8: Outflow | D8: ='Memorial Parks - Outlay'!C32 -> -68169.15 | E8: ='Memorial Parks - Outlay'!D32 -> -77676.3 | F8: ='Memorial Parks - Outlay'!E32 -> -85335.75 | G8: ='Memorial Parks - Outlay'!F32 -> -91084.5 | H8: ='Memorial Parks - Outlay'!G32 -> -94064.25 | I8: ='Memorial Parks - Outlay'!H32 -> -96825 | J8: ='Memorial Parks - Outlay'!I32 -> -94635 | K8: ='Memorial Parks - Outlay'!J32 -> -91635 | ... M8: ='Memorial Parks - Outlay'!L32 -> -85635
B10: Other IRD | C10: Inflow | D10: ='Other IRD - Outlays'!C39 -> 834486 | E10: ='Other IRD - Outlays'!D39 -> 1001383 | F10: ='Other IRD - Outlays'!E39 -> 1084832 | G10: ='Other IRD - Outlays'!F39 -> 1168280 | H10: ='Other IRD - Outlays'!G39 -> 1084832 | I10: ='Other IRD - Outlays'!H39 -> 917935 | J10: ='Other IRD - Outlays'!I39 -> 751037 | K10: ='Other IRD - Outlays'!J39 -> 584140 | ... M10: ='Other IRD - Outlays'!L39 -> 417243
C11: Outflow | D11: ='Other IRD - Outlays'!C40 -> -735273.72 | E11: ='Other IRD - Outlays'!D40 -> -868719.12 | F11: ='Other IRD - Outlays'!E40 -> -940737.65 | G11: ='Other IRD - Outlays'!F40 -> -1012284.2 | H11: ='Other IRD - Outlays'!G40 -> -947576.46 | I11: ='Other IRD - Outlays'!H40 -> -812303.87 | J11: ='Other IRD - Outlays'!I40 -> -675577.3 | K11: ='Other IRD - Outlays'!J40 -> -538241.45 | ... M11: ='Other IRD - Outlays'!L40 -> -389096.11
C14: Net inflow | D14: =SUMIF(D4:D11,">0") -> 939486 | E14: =SUMIF(E4:E11,">0") -> 1118383 | F14: =SUMIF(F4:F11,">0") -> 1980332 | G14: =SUMIF(G4:G11,">0") -> 2455280 | H14: =SUMIF(H4:H11,">0") -> 2763332 | I14: =SUMIF(I4:I11,">0") -> 2795935 | J14: =SUMIF(J4:J11,">0") -> 3205037 | K14: =SUMIF(K4:K11,">0") -> 3230140 | ... M14: =SUMIF(M4:M11,">0") -> 2487243 | P14: use for graphs
C15: Net outflow | D15: =SUMIF(D4:D11,"<0") -> -948442.87 | E15: =SUMIF(E4:E11,"<0") -> -1026395.4 | F15: =SUMIF(F4:F11,"<0") -> -1725919.8 | G15: =SUMIF(G4:G11,"<0") -> -2133138.3 | H15: =SUMIF(H4:H11,"<0") -> -2403333.5 | I15: =SUMIF(I4:I11,"<0") -> -2435783.3 | J15: =SUMIF(J4:J11,"<0") -> -2797751.5 | K15: =SUMIF(K4:K11,"<0") -> -2823377.2 | ... M15: =SUMIF(M4:M11,"<0") -> -2164347.1
C16: Net flow | D16: =SUM(D4:D11) -> -8956.87 | E16: =SUM(E4:E11) -> 91987.58 | F16: =SUM(F4:F11) -> 254412.2 | G16: =SUM(G4:G11) -> 322141.67 | H16: =SUM(H4:H11) -> 359998.49 | I16: =SUM(I4:I11) -> 360151.73 | J16: =SUM(J4:J11) -> 407285.5 | K16: =SUM(K4:K11) -> 406762.75 | ... M16: =SUM(M4:M11) -> 322895.89
C17: Cumulative flow | D17: =D16 -> -8956.87 | E17: =D17+E16 -> 83030.71 | F17: =E17+F16 -> 337442.91 | G17: =F17+G16 -> 659584.58 | H17: =G17+H16 -> 1019583.1 | I17: =H17+I16 -> 1379734.8 | J17: =I17+J16 -> 1787020.3 | K17: =J17+K16 -> 2193783 | L17: =K17+L16 -> 2553411.7 | M17: =L17+M16 -> 2876307.6
C18: FCF margin (after tax) | D18: =D16/D14*100 -> -0.95337983 | E18: =E16/E14*100 -> 8.2250517 | F18: =F16/F14*100 -> 12.846947 | G18: =G16/G14*100 -> 13.120364 | H18: =H16/H14*100 -> 13.027696 | I18: =I16/I14*100 -> 12.881263 | J18: =J16/J14*100 -> 12.707669 | K18: =K16/K14*100 -> 12.592728 | ... M18: =M16/M14*100 -> 12.982081
B20: Quick check | C20: Sum | D20: =SUM(D14:D15) -> -8956.87 | E20: =SUM(E14:E15) -> 91987.58 | F20: =SUM(F14:F15) -> 254412.2 | G20: =SUM(G14:G15) -> 322141.67 | H20: =SUM(H14:H15) -> 359998.49 | I20: =SUM(I14:I15) -> 360151.73 | J20: =SUM(J14:J15) -> 407285.5 | K20: =SUM(K14:K15) -> 406762.75 | ... M20: =SUM(M14:M15) -> 322895.89
C21: Variance | D21: =D16-D20 -> 0 | E21: =E16-E20 -> -1.1641532e-10 | F21: =F16-F20 -> 0 | G21: =G16-G20 -> 0 | H21: =H16-H20 -> 0 | I21: =I16-I20 -> 0 | J21: =J16-J20 -> 0 | K21: =K16-K20 -> 0 | ... M21: =M16-M20 -> 0
B23: Projects as a percentage of business over time
B24: Bankenveld | C24: Inflow | D24: =D4/D14 -> 0 | E24: =E4/E14 -> 0 | F24: =F4/F14 -> 0.38781376 | G24: =G4/G14 -> 0.46919292 | H24: =H4/H14 -> 0.55585069 | I24: =I4/I14 -> 0.61804012 | J24: =J4/J14 -> 0.71886846 | K24: =K4/K14 -> 0.77272193 | ... M24: =M4/M14 -> 0.77193905
C25: Outflow | D25: =D5/D15 -> 0.15288217 | E25: =E5/E15 -> 0.07794267 | F25: =F5/F15 -> 0.40549184 | G25: =G5/G15 -> 0.48274863 | H25: =H5/H15 -> 0.56658503 | I25: =I5/I15 -> 0.62676118 | J25: =J5/J15 -> 0.72470311 | K25: =K5/K15 -> 0.77690673 | ... M25: =M5/M15 -> 0.78065851
B27: Memorial Parks | C27: Inflow | D27: =D7/D15 -> -0.11070778 | E27: =E7/E15 -> -0.11399116 | F27: =F7/F15 -> -0.073873653 | G27: =G7/G15 -> -0.063287035 | H27: =H7/H15 -> -0.059292645 | I27: =I7/I15 -> -0.061581834 | J27: =J7/J15 -> -0.053614483 | K27: =K7/K15 -> -0.053127863 | ... M27: =M7/M15 -> -0.069304965
C28: Outflow | D28: =D8/D15 -> 0.071874809 | E28: =E8/E15 -> 0.075678728 | F28: =F8/F15 -> 0.049443636 | G28: =G8/G15 -> 0.042699762 | H28: =H8/H15 -> 0.039139075 | I28: =I8/I15 -> 0.039751074 | J28: =J8/J15 -> 0.033825377 | K28: =K8/K15 -> 0.032455812 | ... M28: =M8/M15 -> 0.039566204
B30: Other IRD | C30: Inflow | D30: =D10/D14 -> 0.88823676 | E30: =E10/E14 -> 0.89538468 | F30: =F10/F14 -> 0.5478031 | G30: =G10/G14 -> 0.47582353 | H30: =H10/H14 -> 0.39258113 | I30: =I10/I14 -> 0.32831057 | J30: =J10/J14 -> 0.23433021 | K30: =K10/K14 -> 0.18084046 | ... M30: =M10/M14 -> 0.16775321
C31: Outflow | D31: =D11/D15 -> 0.77524303 | E31: =E11/E15 -> 0.8463786 | F31: =F11/F15 -> 0.54506452 | G31: =G11/G15 -> 0.47455161 | H31: =H11/H15 -> 0.39427589 | I31: =I11/I15 -> 0.33348774 | J31: =J11/J15 -> 0.24147152 | K31: =K11/K15 -> 0.19063745 | ... M31: =M11/M15 -> 0.17977528

Sheet Bankenveld - Outlay
A1: Bankenveld Outlay | U1: Notes
A2: Joint venture with Eris Property Fund
A3: Between 20000 and 25000 residential opportunities – of which CGR obtains 100% of the residential revenue
A4: Capex is split due to JV with Eris
A6: Only edit the pink blocks the rest is dynamic
A7: Assumptions (R’000s) | C7: 2026 | D7: 2027 | E7: 2028 | F7: 2029 | G7: 2030 | H7: 2031 | I7: 2032 | J7: 2033 | K7: 2034 | L7: 2035 | M7: 2036 | N7: 2037 | O7: 2038 | P7: 2039 | Q7: 2040 | R7: 2041 | S7: 2042
A8: Year | C8: 1 | D8: 2 | E8: 3 | F8: 4 | G8: 5 | H8: 6 | I8: 7 | J8: 8 | K8: 9 | L8: 10 | M8: 11 | N8: 12 | O8: 13 | P8: 14 | Q8: 15 | R8: 16 | S8: 17 | U8: [Note 1]
A9: Arbitrarily place assumptions here and it’ll calculate the % below | B9: =SUM(C9:S9) -> 100 | C9: 0 | D9: 0 | E9: 4 | F9: 6 | G9: 8 | H9: 9 | I9: 12 | J9: 13 | K9: 11 | L9: 10 | M9: 9 | N9: 5 | O9: 4 | P9: 3 | Q9: 3 | R9: 2 | S9: 1 | U9: use whole numbers
A10: Revenue recognition (% of total residential based revenue) | C10: =C9/$B$9 -> 0 | D10: =D9/$B$9 -> 0 | E10: =E9/$B$9 -> 0.04 | F10: =F9/$B$9 -> 0.06 | G10: =G9/$B$9 -> 0.08 | H10: =H9/$B$9 -> 0.09 | I10: =I9/$B$9 -> 0.12 | J10: =J9/$B$9 -> 0.13 | ... S10: =S9/$B$9 -> 0.01 | U10: needs to make up 100%
A12: CAPEX Spend | U12: [Note 2]
A13: - Bulk Infrastructure (R158m announced & front loaded) | C13: 110000 | D13: 48000
A14: - Incremetal site operating expenditure (security, financing etc) | C14: 35000 | D14: 32000 | E14: 28000 | F14: 22000 | G14: 18000 | H14: 15000 | I14: 12000 | J14: 10000 | K14: 10000 | L14: 10000 | M14: 8000 | N14: 8000 | O14: 6000 | P14: 6000 | Q14: 5000 | R14: 4000 | S14: 4000
A15: Capex (R’000’s) | B15: =SUM(C15:S15) -> 391000 | C15: =SUM(C12:C14) -> 145000 | D15: =SUM(D12:D14) -> 80000 | E15: =SUM(E12:E14) -> 28000 | F15: =SUM(F12:F14) -> 22000 | G15: =SUM(G12:G14) -> 18000 | H15: =SUM(H12:H14) -> 15000 | I15: =SUM(I12:I14) -> 12000 | J15: =SUM(J12:J14) -> 10000 | ... S15: =SUM(S12:S14) -> 4000
U17: based on Calgro’s historical cost margin
A18: Total Project estimates (R’000) | D18: Units | E18: Price per unit
A19: Total project revenue (est.) | C19: =D19*E19 -> 19200000 | D19: 24000 | E19: 800
A20: CGR Share of Capex (est.) | C20: 0.6
A21: Operating Cost (% of Revenue | C21: 0.76 | D21: -> consider making this decline in later years as costs decrease
A22: Tax rate (%) | C22: 0.27
A23: Revenue realisation drag through working capital | C23: 0.05
A25: Net cashflows (J-curve) (R ‘000) | C25: 2026 | D25: 2027 | E25: 2028 | F25: 2029 | G25: 2030 | H25: 2031 | I25: 2032 | J25: 2033 | K25: 2034 | L25: 2035 | M25: 2036 | N25: 2037 | O25: 2038 | P25: 2039 | Q25: 2040 | R25: 2041 | S25: 2042
A26: [=] Project revenue | C26: =$C$19*C10 -> 0 | D26: =$C$19*D10 -> 0 | E26: =$C$19*E10 -> 768000 | F26: =$C$19*F10 -> 1152000 | G26: =$C$19*G10 -> 1536000 | H26: =$C$19*H10 -> 1728000 | I26: =$C$19*I10 -> 2304000 | J26: =$C$19*J10 -> 2496000 | ... S26: =$C$19*S10 -> 192000
A27: [-] Operating costs | C27: =-C26*$C$21 -> 0 | D27: =-D26*$C$21 -> 0 | E27: =-E26*$C$21 -> -583680 | F27: =-F26*$C$21 -> -875520 | G27: =-G26*$C$21 -> -1167360 | H27: =-H26*$C$21 -> -1313280 | I27: =-I26*$C$21 -> -1751040 | J27: =-J26*$C$21 -> -1896960 | ... S27: =-S26*$C$21 -> -145920
A28: [=] Gross Profit | C28: =SUM(C26:C27) -> 0 | D28: =SUM(D26:D27) -> 0 | E28: =SUM(E26:E27) -> 184320 | F28: =SUM(F26:F27) -> 276480 | G28: =SUM(G26:G27) -> 368640 | H28: =SUM(H26:H27) -> 414720 | I28: =SUM(I26:I27) -> 552960 | J28: =SUM(J26:J27) -> 599040 | ... S28: =SUM(S26:S27) -> 46080
A29: [-] CAPEX | C29: =-C15 -> -145000 | D29: =-D15 -> -80000 | E29: =-E15 -> -28000 | F29: =-F15 -> -22000 | G29: =-G15 -> -18000 | H29: =-H15 -> -15000 | I29: =-I15 -> -12000 | J29: =-J15 -> -10000 | ... S29: =-S15 -> -4000
A30: [-] Change in working capital | C30: =-C26*$C$23 -> 0 | D30: =-D26*$C$23 -> 0 | E30: =-E26*$C$23 -> -38400 | F30: =-F26*$C$23 -> -57600 | G30: =-G26*$C$23 -> -76800 | H30: =-H26*$C$23 -> -86400 | I30: =-I26*$C$23 -> -115200 | J30: =-J26*$C$23 -> -124800 | ... S30: =-S26*$C$23 -> -9600
A31: [=] Pre-Tax project FCF | C31: =SUM(C28:C30) -> -145000 | D31: =SUM(D28:D30) -> -80000 | E31: =SUM(E28:E30) -> 117920 | F31: =SUM(F28:F30) -> 196880 | G31: =SUM(G28:G30) -> 273840 | H31: =SUM(H28:H30) -> 313320 | I31: =SUM(I28:I30) -> 425760 | J31: =SUM(J28:J30) -> 464240 | ... S31: =SUM(S28:S30) -> 32480
A32: [-] Tax (on GP if positive, else 0) | C32: =-C28*$C$22 -> 0 | D32: =-D28*$C$22 -> 0 | E32: =-E28*$C$22 -> -49766.4 | F32: =-F28*$C$22 -> -74649.6 | G32: =-G28*$C$22 -> -99532.8 | H32: =-H28*$C$22 -> -111974.4 | I32: =-I28*$C$22 -> -149299.2 | J32: =-J28*$C$22 -> -161740.8 | ... S32: =-S28*$C$22 -> -12441.6
A33: [=] After Tax Free-cashflow | C33: =SUM(C31:C32) -> -145000 | D33: =SUM(D31:D32) -> -80000 | E33: =SUM(E31:E32) -> 68153.6 | F33: =SUM(F31:F32) -> 122230.4 | G33: =SUM(G31:G32) -> 174307.2 | H33: =SUM(H31:H32) -> 201345.6 | I33: =SUM(I31:I32) -> 276460.8 | J33: =SUM(J31:J32) -> 302499.2 | ... S33: =SUM(S31:S32) -> 20038.4
A34: Cumulative Free cashflow (R’ 000s) | C34: =C33 -> -145000 | D34: =C34+D33 -> -225000 | E34: =D34+E33 -> -156846.4 | F34: =E34+F33 -> -34616 | G34: =F34+G33 -> 139691.2 | H34: =G34+H33 -> 341036.8 | I34: =H34+I33 -> 617497.6 | J34: =I34+J33 -> 919996.8 | K34: =J34+K33 -> 1174419.2 | ... S34: =R34+S33 -> 2012840
A36: Net cashflows (J-curve) (R ‘000) | C36: 2026 | D36: 2027 | E36: 2028 | F36: 2029 | G36: 2030 | H36: 2031 | I36: 2032 | J36: 2033 | K36: 2034 | L36: 2035 | M36: 2036 | N36: 2037 | O36: 2038 | P36: 2039 | Q36: 2040 | R36: 2041 | S36: 2042
A37: Gross margin (%) | C37: =IF(C28=0,0,C28/C26) -> 0 | D37: =IF(D28=0,0,D28/D26) -> 0 | E37: =IF(E28=0,0,E28/E26) -> 0.24 | F37: =IF(F28=0,0,F28/F26) -> 0.24 | G37: =IF(G28=0,0,G28/G26) -> 0.24 | H37: =IF(H28=0,0,H28/H26) -> 0.24 | I37: =IF(I28=0,0,I28/I26) -> 0.24 | J37: =IF(J28=0,0,J28/J26) -> 0.24 | ... S37: =IF(S28=0,0,S28/S26) -> 0.24
A38: FCF Margin (pre-tax, %) | C38: =IF(C31<=0,0,C31/C26) -> 0 | D38: =IF(D31<=0,0,D31/D26) -> 0 | E38: =IF(E31<=0,0,E31/E26) -> 0.15354167 | F38: =IF(F31<=0,0,F31/F26) -> 0.17090278 | G38: =IF(G31<=0,0,G31/G26) -> 0.17828125 | H38: =IF(H31<=0,0,H31/H26) -> 0.18131944 | I38: =IF(I31<=0,0,I31/I26) -> 0.18479167 | J38: =IF(J31<=0,0,J31/J26) -> 0.18599359 | ... S38: =IF(S31<=0,0,S31/S26) -> 0.16916667
A40: Outflows | C40: =C27+C29+C30+C32 -> -145000 | D40: =D27+D29+D30+D32 -> -80000 | E40: =E27+E29+E30+E32 -> -699846.4 | F40: =F27+F29+F30+F32 -> -1029769.6 | G40: =G27+G29+G30+G32 -> -1361692.8 | H40: =H27+H29+H30+H32 -> -1526654.4 | I40: =I27+I29+I30+I32 -> -2027539.2 | J40: =J27+J29+J30+J32 -> -2193500.8 | ... S40: =S27+S29+S30+S32 -> -171961.6
A41: Inflows | C41: =C26 -> 0 | D41: =D26 -> 0 | E41: =E26 -> 768000 | F41: =F26 -> 1152000 | G41: =G26 -> 1536000 | H41: =H26 -> 1728000 | I41: =I26 -> 2304000 | J41: =J26 -> 2496000 | ... S41: =S26 -> 192000
A44: Some notes on what informed my decisions
A45: [Note 1] Revenue notes
A46: - infrastructure costs to calgro is specifically R158m in the first two years
A47: -overall revenue is said to be R18 billion over 15 to 20 years.
A48: - I believe it will be more given increased mid-term inflation expectations
...

Sheet Memorial Parks - Outlay
A1: Memorial Parks — J-Curve Model
A2: Calgro M3 Holdings (CGR.JO) · Annuity-style income stream · 6 parks
A3: Nasrec, Fourways, Durbanville, Enokuthula, Bloemfontein, Rustenburg (launched Dec 2024)
A4: Pink cells = editable assumptions
A6: Assumptions (R'000s) | C6: 2026 | D6: 2027 | E6: 2028 | F6: 2029 | G6: 2030 | H6: 2031 | I6: 2032 | J6: 2033 | K6: 2034 | L6: 2035 | M6: 2036
A7: Revenue recognition (% of steady state revenue) | C7: 0.7 | D7: 0.78 | E7: 0.85 | F7: 0.9 | G7: 0.95 | H7: 1 | I7: 1 | J7: 1 | K7: 1 | L7: 1 | M7: 1
A8: Cost spend — incremental site operating exp (%) | C8: 0.05 | D8: 0.08 | E8: 0.1 | F8: 0.12 | G8: 0.12 | H8: 0.12 | I8: 0.12 | J8: 0.1 | K8: 0.08 | L8: 0.06 | M8: 0.05 | N8: =SUM(C8:M8) -> 1
A9: Operating costs (% of revenue) | C9: 0.451 | D9: 0.43 | E9: 0.41 | F9: 0.39 | G9: 0.37 | H9: 0.35 | I9: 0.33 | J9: 0.33 | K9: 0.33 | L9: 0.33 | M9: 0.33
A10: Cost as % of revenue | C10: =C8+C9 -> 0.501 | D10: =D8+D9 -> 0.51 | E10: =E8+E9 -> 0.51 | F10: =F8+F9 -> 0.51 | G10: =G8+G9 -> 0.49 | H10: =H8+H9 -> 0.47 | I10: =I8+I9 -> 0.45 | J10: =J8+J9 -> 0.43 | ... M10: =M8+M9 -> 0.38
A12: Total Project Estimates (R'000)
C13: No of parks | D13: Maturity revenue each (R'000s)
A14: Steady-state revenue (all parks) (R'000) | B14: 150000 | C14: 6 | D14: 25000 | E14: ← Nasrec pulls avg up at 20,026 grave capacity
A15: Tax rate (%) | B15: 0.27
A17: Net cashflows (J-curve) (R'000) | C17: 2026 | D17: 2027 | E17: 2028 | F17: 2029 | G17: 2030 | H17: 2031 | I17: 2032 | J17: 2033 | K17: 2034 | L17: 2035 | M17: 2036
A18: [+] Revenue | C18: =$B$14*C7 -> 105000 | D18: =$B$14*D7 -> 117000 | E18: =$B$14*E7 -> 127500 | F18: =$B$14*F7 -> 135000 | G18: =$B$14*G7 -> 142500 | H18: =$B$14*H7 -> 150000 | I18: =$B$14*I7 -> 150000 | J18: =$B$14*J7 -> 150000 | ... M18: =$B$14*M7 -> 150000
A19: [-] Operating costs | C19: =-C18*C9 -> -47355 | D19: =-D18*D9 -> -50310 | E19: =-E18*E9 -> -52275 | F19: =-F18*F9 -> -52650 | G19: =-G18*G9 -> -52725 | H19: =-H18*H9 -> -52500 | I19: =-I18*I9 -> -49500 | J19: =-J18*J9 -> -49500 | ... M19: =-M18*M9 -> -49500
A20: [=] Gross Profit | C20: =C18+C19 -> 57645 | D20: =D18+D19 -> 66690 | E20: =E18+E19 -> 75225 | F20: =F18+F19 -> 82350 | G20: =G18+G19 -> 89775 | H20: =H18+H19 -> 97500 | I20: =I18+I19 -> 100500 | J20: =J18+J19 -> 100500 | ... M20: =M18+M19 -> 100500
A21: [-] CAPEX | C21: -5250 | D21: -9360 | E21: -12750 | F21: -16200 | G21: -17100 | H21: -18000 | I21: -18000 | J21: -15000 | K21: -12000 | L21: -9000 | M21: -7500
A22: [=] Pre-Tax project FCF | C22: =C20+C21 -> 52395 | D22: =D20+D21 -> 57330 | E22: =E20+E21 -> 62475 | F22: =F20+F21 -> 66150 | G22: =G20+G21 -> 72675 | H22: =H20+H21 -> 79500 | I22: =I20+I21 -> 82500 | J22: =J20+J21 -> 85500 | ... M22: =M20+M21 -> 93000
A23: [-] Tax (on GP if positive, else 0) | C23: =IF(C20>0,-C20*$B$15,0) -> -15564.15 | D23: =IF(D20>0,-D20*$B$15,0) -> -18006.3 | E23: =IF(E20>0,-E20*$B$15,0) -> -20310.75 | F23: =IF(F20>0,-F20*$B$15,0) -> -22234.5 | G23: =IF(G20>0,-G20*$B$15,0) -> -24239.25 | H23: =IF(H20>0,-H20*$B$15,0) -> -26325 | I23: =IF(I20>0,-I20*$B$15,0) -> -27135 | J23: =IF(J20>0,-J20*$B$15,0) -> -27135 | ... M23: =IF(M20>0,-M20*$B$15,0) -> -27135
A24: [=] After Tax FCF | C24: =C22+C23 -> 36830.85 | D24: =D22+D23 -> 39323.7 | E24: =E22+E23 -> 42164.25 | F24: =F22+F23 -> 43915.5 | G24: =G22+G23 -> 48435.75 | H24: =H22+H23 -> 53175 | I24: =I22+I23 -> 55365 | J24: =J22+J23 -> 58365 | ... M24: =M22+M23 -> 65865
A25: Cumulative FCF (R'000s) | C25: =C24 -> 36830.85 | D25: =C25+D24 -> 76154.55 | E25: =D25+E24 -> 118318.8 | F25: =E25+F24 -> 162234.3 | G25: =F25+G24 -> 210670.05 | H25: =G25+H24 -> 263845.05 | I25: =H25+I24 -> 319210.05 | J25: =I25+J24 -> 377575.05 | K25: =J25+K24 -> 438940.05 | ... M25: =L25+M24 -> 569170.05
A27: Margin Analysis | C27: 2026 | D27: 2027 | E27: 2028 | F27: 2029 | G27: 2030 | H27: 2031 | I27: 2032 | J27: 2033 | K27: 2034 | L27: 2035 | M27: 2036
A28: Gross margin (%) | C28: =IF(C18=0,0,C20/C18) -> 0.549 | D28: =IF(D18=0,0,D20/D18) -> 0.57 | E28: =IF(E18=0,0,E20/E18) -> 0.59 | F28: =IF(F18=0,0,F20/F18) -> 0.61 | G28: =IF(G18=0,0,G20/G18) -> 0.63 | H28: =IF(H18=0,0,H20/H18) -> 0.65 | I28: =IF(I18=0,0,I20/I18) -> 0.67 | J28: =IF(J18=0,0,J20/J18) -> 0.67 | ... M28: =IF(M18=0,0,M20/M18) -> 0.67
A29: FCF Margin (pre-tax, %) | C29: =IF(C18=0,0,C22/C18) -> 0.499 | D29: =IF(D18=0,0,D22/D18) -> 0.49 | E29: =IF(E18=0,0,E22/E18) -> 0.49 | F29: =IF(F18=0,0,F22/F18) -> 0.49 | G29: =IF(G18=0,0,G22/G18) -> 0.51 | H29: =IF(H18=0,0,H22/H18) -> 0.53 | I29: =IF(I18=0,0,I22/I18) -> 0.55 | J29: =IF(J18=0,0,J22/J18) -> 0.57 | ... M29: =IF(M18=0,0,M22/M18) -> 0.62
A30: FCF Margin (after tax) | C30: =IF(C18=0,0,C24/C18) -> 0.35077 | D30: =IF(D18=0,0,D24/D18) -> 0.3361 | E30: =IF(E18=0,0,E24/E18) -> 0.3307 | F30: =IF(F18=0,0,F24/F18) -> 0.3253 | G30: =IF(G18=0,0,G24/G18) -> 0.3399 | H30: =IF(H18=0,0,H24/H18) -> 0.3545 | I30: =IF(I18=0,0,I24/I18) -> 0.3691 | J30: =IF(J18=0,0,J24/J18) -> 0.3891 | ... M30: =IF(M18=0,0,M24/M18) -> 0.4391
A32: Outflows | C32: =C19+C21+C23 -> -68169.15 | D32: =D19+D21+D23 -> -77676.3 | E32: =E19+E21+E23 -> -85335.75 | F32: =F19+F21+F23 -> -91084.5 | G32: =G19+G21+G23 -> -94064.25 | H32: =H19+H21+H23 -> -96825 | I32: =I19+I21+I23 -> -94635 | J32: =J19+J21+J23 -> -91635 | ... M32: =M19+M21+M23 -> -84135
A33: Inflows | C33: =C18 -> 105000 | D33: =D18 -> 117000 | E33: =E18 -> 127500 | F33: =F18 -> 135000 | G33: =G18 -> 142500 | H33: =H18 -> 150000 | I33: =I18 -> 150000 | J33: =J18 -> 150000 | ... M33: =M18 -> 150000
A35: J-Curve Phase | C35: EXPAND | D35: EXPAND | E35: RAMP | F35: RAMP | G35: GROW | H35: GROW | I35: MATURE | J35: STEADY | K35: STEADY | L35: STEADY | M35: STEADY
A37: NOTES
A38: 1. Memorial Parks = Annuity business. Revenue stabilises once park reaches capacity.
A39: 2. Six parks: Nasrec (2014), Fourways (2015), Enokuthula (2020), Durbanville (2019), Bloemfontein (2019), Rustenburg (2024)
A40: 3. Actual FY2026 cash received: Nasrec R48.9M, Fourways R32.9M, Durbanville R18.6M. Total R106.9M.
A41: Model 2026 revenue = 70% x R150M = R105M. Calibrated to actual 2026 results within R2M.
A42: 4. Steady state R25M per park x 6 = R150M. Nasrec outlier at R48.9M (20,026 grave capacity).
A43: 5. Cost declines as parks mature (scale). Historical GP: 54.9% (2026), 50.9% (2025).
A44: FY2026 ACTUAL UPDATE: Revenue R86M (2025: R66M). GP margin 54.9%. Cash collected R106.9M.

Sheet Other IRD - Outlays
A1: Fleurhof & South Hills & Belhar -J-Curve Model
A2: Calgro M3 Holdings (CGR.JO) · Active IRD Projects
A3: Projects: Fleurhof (est. 2009), South Hills (est. 2014), Belhar CBD (est. 2012)
A4: Pink cells = editable assumptions
A6: KEY ASSUMPTIONS | C6: 2026 | D6: 2027 | E6: 2028 | F6: 2029 | G6: 2030 | H6: 2031 | I6: 2032 | J6: 2033 | K6: 2034 | L6: 2035
A7: Revenue Recognition (% of remaining value) | C7: 0.1 | D7: 0.12 | E7: 0.13 | F7: 0.14 | G7: 0.13 | H7: 0.11 | I7: 0.09 | J7: 0.07 | K7: 0.06 | L7: 0.05 | M7: =SUM(C7:L7) -> 1
A8: CAPEX (% of remaining CAPEX) [Note 1] | C8: 0.12 | D8: 0.13 | E8: 0.14 | F8: 0.13 | G8: 0.12 | H8: 0.11 | I8: 0.09 | J8: 0.07 | K8: 0.05 | L8: 0.04 | M8: =SUM(C8:L8) -> 1
A9: Operating Cost (% of Revenue) [Note 3] | C9: 0.68 | D9: 0.67 | E9: 0.67 | F9: 0.68 | G9: 0.69 | H9: 0.7 | I9: 0.72 | J9: 0.75 | K9: 0.75 | L9: 0.78
A11: Remaining Project Revenue Calculation
A12: Project | B12: Units | C12: Cost per unit (R'000s) | D12: Revenue (R'000s)
A13: Fleurhof | B13: 4785 | C13: 900 | D13: =B13*C13 -> 4306500
A14: South Hills | B14: 4495 | C14: 680 | D14: =B14*C14 -> 3056600
A15: Belhar (incl. 225 student equiv) | B15: 1534 | C15: 640 | D15: =B15*C15 -> 981760 | E15: 4 students = 1 unit (900 beds / 4 = 225 equiv)
A17: Total Estimates (R'000)
A18: Remaining revenue (R'000s) | B18: =D13+D14+D15 -> 8344860
A19: Remaining CAPEX [Note 1] | B19: 450000
A20: Tax Rate (%) | B20: 0.27
A21: Working capital drag % [Note 4] | B21: 0.05
A23: Net cashflows (J-curve) (R'000) | C23: 2026 | D23: 2027 | E23: 2028 | F23: 2029 | G23: 2030 | H23: 2031 | I23: 2032 | J23: 2033 | K23: 2034 | L23: 2035
A24: [+] Revenue | C24: 834486 | D24: 1001383 | E24: 1084832 | F24: 1168280 | G24: 1084832 | H24: 917935 | I24: 751037 | J24: 584140 | K24: 500692 | L24: 417243
A25: [-] Operating Costs | C25: -567450 | D25: -670927 | E25: -726837 | F25: -794431 | G25: -748534 | H25: -642554 | I25: -540747 | J25: -438105 | K25: -375519 | L25: -325450
A26: [=] Gross Profit | C26: =C24+C25 -> 267036 | D26: =D24+D25 -> 330456 | E26: =E24+E25 -> 357995 | F26: =F24+F25 -> 373849 | G26: =G24+G25 -> 336298 | H26: =H24+H25 -> 275381 | I26: =I24+I25 -> 210290 | J26: =J24+J25 -> 146035 | ... L26: =L24+L25 -> 91793
A27: [-] CAPEX | C27: -54000 | D27: -58500 | E27: -63000 | F27: -58500 | G27: -54000 | H27: -49500 | I27: -40500 | J27: -31500 | K27: -22500 | L27: -18000
A28: [-] Change in Working Capital | C28: -41724 | D28: -50069 | E28: -54242 | F28: -58414 | G28: -54242 | H28: -45897 | I28: -37552 | J28: -29207 | K28: -25035 | L28: -20862
A29: [=] Pre-Tax FCF | C29: =C26+C27+C28 -> 171312 | D29: =D26+D27+D28 -> 221887 | E29: =E26+E27+E28 -> 240753 | F29: =F26+F27+F28 -> 256935 | G29: =G26+G27+G28 -> 228056 | H29: =H26+H27+H28 -> 179984 | I29: =I26+I27+I28 -> 132238 | J29: =J26+J27+J28 -> 85328 | ... L29: =L26+L27+L28 -> 52931
A30: [-] Tax (on GP if positive) | C30: =IF(C26>0,-C26*$B$20,0) -> -72099.72 | D30: =IF(D26>0,-D26*$B$20,0) -> -89223.12 | E30: =IF(E26>0,-E26*$B$20,0) -> -96658.65 | F30: =IF(F26>0,-F26*$B$20,0) -> -100939.23 | G30: =IF(G26>0,-G26*$B$20,0) -> -90800.46 | H30: =IF(H26>0,-H26*$B$20,0) -> -74352.87 | I30: =IF(I26>0,-I26*$B$20,0) -> -56778.3 | J30: =IF(J26>0,-J26*$B$20,0) -> -39429.45 | ... L30: =IF(L26>0,-L26*$B$20,0) -> -24784.11
A31: [=] After-Tax FCF | C31: =C29+C30 -> 99212.28 | D31: =D29+D30 -> 132663.88 | E31: =E29+E30 -> 144094.35 | F31: =F29+F30 -> 155995.77 | G31: =G29+G30 -> 137255.54 | H31: =H29+H30 -> 105631.13 | I31: =I29+I30 -> 75459.7 | J31: =J29+J30 -> 45898.55 | ... L31: =L29+L30 -> 28146.89
A32: Cumulative FCF | C32: =C31 -> 99212.28 | D32: =C32+D31 -> 231876.16 | E32: =D32+E31 -> 375970.51 | F32: =E32+F31 -> 531966.28 | G32: =F32+G31 -> 669221.82 | H32: =G32+H31 -> 774852.95 | I32: =H32+I31 -> 850312.65 | J32: =I32+J31 -> 896211.2 | K32: =J32+K31 -> 940052.49 | L32: =K32+L31 -> 968199.38
A34: Margin Analysis | C34: 2026 | D34: 2027 | E34: 2028 | F34: 2029 | G34: 2030 | H34: 2031 | I34: 2032 | J34: 2033 | K34: 2034 | L34: 2035
A35: Gross margins (%) | C35: =IF(C24=0,0,C26/C24) -> 0.32000058 | D35: =IF(D24=0,0,D26/D24) -> 0.32999961 | E35: =IF(E24=0,0,E26/E24) -> 0.33000041 | F35: =IF(F24=0,0,F26/F24) -> 0.31999949 | G35: =IF(G24=0,0,G26/G24) -> 0.31000007 | H35: =IF(H24=0,0,H26/H24) -> 0.30000054 | I35: =IF(I24=0,0,I26/I24) -> 0.27999952 | J35: =IF(J24=0,0,J26/J24) -> 0.25 | ... L35: =IF(L24=0,0,L26/L24) -> 0.2199989
A36: FCF margins (pre-tax, %) | C36: =IF(C24=0,0,C29/C24) -> 0.20529044 | D36: =IF(D24=0,0,D29/D24) -> 0.22158055 | E36: =IF(E24=0,0,E29/E24) -> 0.22192653 | F36: =IF(F24=0,0,F29/F24) -> 0.21992587 | G36: =IF(G24=0,0,G29/G24) -> 0.21022241 | H36: =IF(H24=0,0,H29/H24) -> 0.19607489 | I36: =IF(I24=0,0,I29/I24) -> 0.17607388 | J36: =IF(J24=0,0,J29/J24) -> 0.14607457 | ... L36: =IF(L24=0,0,L29/L24) -> 0.12685893
A37: FCF margins (after tax) | C37: =IF(C24=0,0,C31/C24) -> 0.11889029 | D37: =IF(D24=0,0,D31/D24) -> 0.13248066 | E37: =IF(E24=0,0,E31/E24) -> 0.13282642 | F37: =IF(F24=0,0,F31/F24) -> 0.13352601 | G37: =IF(G24=0,0,G31/G24) -> 0.12652239 | H37: =IF(H24=0,0,H31/H24) -> 0.11507474 | I37: =IF(I24=0,0,I31/I24) -> 0.10047401 | J37: =IF(J24=0,0,J31/J24) -> 0.078574571 | ... L37: =IF(L24=0,0,L31/L24) -> 0.067459226
A39: Inflows | C39: =C24 -> 834486 | D39: =D24 -> 1001383 | E39: =E24 -> 1084832 | F39: =F24 -> 1168280 | G39: =G24 -> 1084832 | H39: =H24 -> 917935 | I39: =I24 -> 751037 | J39: =J24 -> 584140 | ... L39: =L24 -> 417243
A40: Outflows | C40: =C25+C27+C28+C30 -> -735273.72 | D40: =D25+D27+D28+D30 -> -868719.12 | E40: =E25+E27+E28+E30 -> -940737.65 | F40: =F25+F27+F28+F30 -> -1012284.2 | G40: =G25+G27+G28+G30 -> -947576.46 | H40: =H25+H27+H28+H30 -> -812303.87 | I40: =I25+I27+I28+I30 -> -675577.3 | J40: =J25+J27+J28+J30 -> -538241.45 | ... L40: =L25+L27+L28+L30 -> -389096.11
A42: J-Curve Phase | C42: DELIVER | D42: DELIVER | E42: DELIVER | F42: PEAK | G42: PEAK | H42: DECLINE | I42: TAIL | J42: TAIL | K42: TAIL | L42: TAIL
A44: Note 1: CAPEX -R450M total remaining. Conservative given bulk infra substantially complete on all three projects.
A45: Front-loaded as more servicing needed early. ~5% of revenue is reasonable for mature IRD.
A46: Note 2: ASPs sourced directly from CGR 2026 IR pipeline table (CEO/CFO message):
A47: Fleurhof 4785 units @ R900K = R4.306B | South Hills 4495 @ R680K = R3.057B (mgmt optimism discount applied)
A48: Belhar 1309 units + 900 student beds (÷4 = 225 equiv) = 1534 units @ R640K = R982M. Total: R8.344B
...

Sheet Balance Sheet
B1: 2025-02-28 | C1: 2024-02-29 | D1: 2023-02-28 | E1: 2022-02-28
A2: Treasury Shares Number | B2: 17915449 | C2: 18322449 | D2: 18894449 | E2: 18894449
A3: Ordinary Shares Number | B3: 96466126 | C3: 96059126 | D3: 121400069 | E3: 121400069
A4: Share Issued | B4: 114381575 | C4: 114381575 | D4: 140294518 | E4: 140294518
A5: Net Debt | B5: 950999659 | C5: 812158121 | D5: 703747997 | E5: 647953523
A6: Total Debt | B6: 1128648074 | C6: 959537809 | D6: 876362327 | E6: 853684610
A7: Tangible Book Value | B7: 1270771659 | C7: 1114215266 | D7: 985274139 | E7: 803439032
A8: Invested Capital | B8: 2536144370 | C8: 2208661942 | D8: 2021287000 | E8: 1802157338
A9: Working Capital | B9: 1373501666 | C9: 1165268091 | D9: 1123470216 | E9: 897556667
A10: Net Tangible Assets | B10: 1270771659 | C10: 1114215266 | D10: 985274139 | E10: 803439032
A11: Capital Lease Obligations | B11: 22925880 | C11: 24741667 | D11: 11543229 | E11: 14616838
A12: Common Stock Equity | B12: 1430422176 | C12: 1273865800 | D12: 1144924673 | E12: 963089566
A13: Total Capitalization | B13: 2396144370 | C13: 1996911942 | D13: 1144924673 | E13: 963089566
... A22: Total Non Current Liabilities Net Minority Interest | B22: 1331788583 | C22: 1049063328 | D22: 267525022 | E22: 225378217
A23: Other Non Current Liabilities | B23: 140000000 | C23: 211750000 | D23: 15051815
A24: Non Current Pension And Other Postretirement Benefit Plans | C24: 3026639 | D24: 3400451
A25: Non Current Deferred Taxes Liabilities | B25: 366066389 | C25: 326017186 | D25: 267525022 | E25: 213834988
A26: Long Term Debt And Capital Lease Obligation | B26: 965722194 | C26: 723046142 | D26: 884011401 | E26: 11543229
A27: Long Term Capital Lease Obligation | C27: 22921712 | D27: 7649074 | E27: 11543229
A28: Long Term Debt | B28: 965722194 | C28: 723046142 | D28: 876362327
A29: Current Liabilities | B29: 508703581 | C29: 512615934 | D29: 1245924215 | E29: 1250191842
A30: Other Current Liabilities | B30: 631803 | C30: 678439 | D30: 12863856 | E30: 53710783
A31: Current Debt And Capital Lease Obligation | B31: 162925880 | C31: 236491667 | D31: 876362327 | E31: 842141381
A32: Current Capital Lease Obligation | B32: 22925880 | C32: 24741667 | D32: 3894155 | E32: 3073609
A33: Current Debt | B33: 965722194 | C33: 211750000 | D33: 876362327 | E33: 839067772
A34: Pensionand Other Post Retirement Benefit Plans Current | B34: 3258397 | C34: 3026639 | D34: 3400451 | E34: 4828765
A35: Current Provisions | D35: 2187959 | E35: 2259974
A36: Payables | B36: 241226546 | C36: 162092113 | D36: 369561888 | E36: 224684601
A37: Other Payable | B37: 16985905 | C37: 28130037 | D37: 20556592 | E37: 20928996
A38: Dividends Payable | E38: 0
A39: Total Tax Payable | B39: 789669 | C39: 17943095 | D39: 633442 | E39: 18194642
A40: Accounts Payable | B40: 223450972 | C40: 116018981 | D40: 368928446 | E40: 185560963
B41: 45716
A42: Total Assets | B42: 3274167897 | C42: 2836210738 | D42: 2659063172 | E42: 2439255893
A43: Total Non Current Assets | B43: 1391962650 | C43: 1158326713 | D43: 289668741 | E43: 291507384
A44: Other Non Current Assets | C44: 434736127 | D44: 449464431
A45: Non Current Deferred Taxes Assets | B45: 11363028 | C45: 15681504 | D45: 26500218 | E45: 31695226
A46: Other Investments | B46: 19196470 | C46: 16769513 | D46: 14894959
A47: Investmentin Financial Assets | C47: 16769513 | D47: 14894959 | E47: 13927808
A48: Financial Assets Designatedas Fair Value Through Profitor Loss Total | C48: 16769513 | D48: 14894959 | E48: 13927808
...

Sheet Cash Flows
B1: 2025-02-28 | C1: 2024-02-29 | D1: 2023-02-28 | E1: 2022-02-28
A2: Free Cash Flow | B2: 33256027 | C2: 90540546 | D2: 870531 | E2: 128699620
A3: Repurchase Of Capital Stock | B3: 0 | C3: -73016275 | D3: 0 | E3: -9085714
A4: Repayment Of Debt | B4: -158000000 | C4: -232800000 | D4: -194800000 | E4: -107400000
A5: Issuance Of Debt | B5: 305000000 | C5: 288000000 | D5: 230000000 | E5: 0
A6: Capital Expenditure | B6: -972384 | C6: -722708 | D6: -1199014 | E6: -1182125
A7: End Cash Position | B7: 154722535 | C7: 122638021 | D7: 172614330 | E7: 191114249
A8: Beginning Cash Position | B8: 122638021 | C8: 172614330 | D8: 191114249 | E8: 154561255
A9: Changes In Cash | B9: 32084514 | C9: -49976309 | D9: -18499919 | E9: 36552994
A10: Financing Cash Flow | B10: 131273997 | C10: -20364903 | D10: 32126391 | E10: -118864060
A11: Net Other Financing Charges | E11: -9085714
A12: Cash Dividends Paid | B12: -10857999
A13: Net Common Stock Issuance | B13: 0 | C13: -73016275 | D13: 0 | E13: -9085714
A14: Common Stock Payments | B14: 0 | C14: -73016275 | D14: 0 | E14: -9085714
A15: Net Issuance Payments Of Debt | B15: 147000000 | C15: 55200000 | D15: 35200000 | E15: -107400000
A16: Net Long Term Debt Issuance | B16: 147000000 | C16: 55200000 | D16: 35200000 | E16: -107400000
A17: Long Term Debt Payments | B17: -158000000 | C17: -232800000 | D17: -194800000 | E17: -107400000
A18: Long Term Debt Issuance | B18: 305000000 | C18: 288000000 | D18: 230000000 | E18: 0
A19: Investing Cash Flow | B19: -133417894 | C19: -120874660 | D19: -52695855 | E19: 25535309
A20: Net Investment Purchase And Sale | D20: 0 | E20: -286383
A21: Purchase Of Investment | D21: 0 | E21: -286383
A22: Net Investment Properties Purchase And Sale | E22: 0
A23: Purchase Of Investment Properties | E23: 0
A24: Net Business Purchase And Sale | B24: -13200000 | C24: -6900000 | D24: 0 | E24: 500
A25: Sale Of Business | D25: 0 | E25: 500
A26: Purchase Of Business | B26: -13200000 | C26: -6900000 | D26: 0 | E26: 0
A27: Net PPE Purchase And Sale | B27: -972384 | C27: -722708 | D27: -743150 | E27: -1182125
A28: Sale Of PPE | C28: 0 | D28: 455864 | E28: 0
A29: Purchase Of PPE | B29: -972384 | C29: -722708 | D29: -1199014 | E29: -1182125
A30: Operating Cash Flow | B30: 34228411 | C30: 91263254 | D30: 2069545 | E30: 129881745
A31: Taxes Refund Paid | B31: -2659727 | C31: -3487918 | D31: -5197841 | E31: -18022488
A32: Interest Received Cfo | B32: 63092531 | C32: 56905547 | D32: 8003346 | E32: 1983254
A33: Interest Paid Cfo | B33: -134104505 | C33: -111400297 | D33: -90374618 | E33: -82300992
A34: Change In Working Capital | B34: -66802133 | C34: -121451838 | D34: -180385854 | E34: 19807355
A35: Change In Payable | B35: 80589421 | C35: -100591682 | D35: -58464638 | E35: -60947816
A36: Change In Inventory | B36: -4018645 | C36: 8381141 | D36: 127164786 | E36: 52229763
A37: Change In Receivables | B37: -143372909 | C37: -29241297 | D37: -249086002 | E37: 28525408
A38: Other Non Cash Items | B38: -4071424 | C38: -459614 | D38: 10399291 | E38: 20341099
A39: Stock Based Compensation | B39: 4064677 | C39: 6252686 | D39: 4222154 | E39: 3788191
A40: Provisionand Write Offof Assets | B40: 3652484 | C40: 5595247 | D40: 5657460 | E40: 1928630
...

Sheet Close Prices
A1: Date | B1: Close
A2: 39402 | B2: 328.88879
A3: 39405 | B3: 319.89185
A4: 39406 | B4: 309.89523
A5: 39407 | B5: 309.89523
A6: 39408 | B6: 314.89355
A7: 39409 | B7: 309.89523
A8: 39412 | B8: 309.89523
A9: 39413 | B9: 309.89523
A10: 39414 | B10: 299.89862
A11: 39415 | B11: 299.89862
A12: 39416 | B12: 299.89862
A13: 39419 | B13: 299.89862
... A4711: 46163 | B4711: 430

Sheet Growth Estimates
A1: period | B1: stockTrend | C1: indexTrend
A2: 0q | C2: 0.2493
A3: +1q | C3: 0.1899
A4: 0y | C4: 0.2165
A5: +1y | C5: 0.16149999
A6: LTG | C6: 0.122

Sheet Income Statement
B1: 2025-02-28 | C1: 2024-02-29 | D1: 2023-02-28 | E1: 2022-02-28
A2: Tax Effect Of Unusual Items | B2: 336131.14 | C2: 435413.23 | D2: 111757.71 | E2: -1250601
A3: Tax Rate For Calcs | B3: 0.2184 | C3: 0.2712 | D3: 0.2618 | E3: 0.2635
A4: Normalized EBITDA | B4: 272844653 | C4: 328508813 | D4: 299911603 | E4: 230849680
A5: Total Unusual Items | B5: 1539062 | C5: 1605506 | D5: 426882 | E5: -4746114
A6: Total Unusual Items Excluding Goodwill | B6: 1539062 | C6: 1605506 | D6: 426882 | E6: -4746114
A7: Net Income From Continuing Operation Net Minority Interest | B7: 164984085 | C7: 195704717 | D7: 186194542 | E7: 131811216
A8: Reconciled Depreciation | B8: 4159540 | C8: 4052035 | D8: 3941477 | E8: 4000610
A9: Reconciled Cost Of Revenue | B9: 613186506 | C9: 939548121 | D9: 1167622753 | E9: 1039746583
A10: EBITDA | B10: 274383715 | C10: 330114319 | D10: 300338485 | E10: 226103566
A11: EBIT | B11: 270224175 | C11: 326062284 | D11: 296397008 | E11: 222102956
A12: Net Interest Income | B12: 2891297 | C12: -877678 | D12: -11358713 | E12: -26629918
A13: Interest Expense | B13: 57680185 | C13: 57300560 | D13: 44038188 | E13: 42638140
... A33: Special Income Charges | B33: -887895 | C33: -269048 | D33: -540269 | E33: -5360335
A34: Other Special Charges | B34: 887895 | C34: 269048 | D34: 540269
A35: Write Off | C35: 5595247 | D35: 5784350 | E35: 8942648
A36: Restructuring And Mergern Acquisition | D36: 0 | E36: -3582313
A37: Net Non Operating Interest Income Expense | B37: 2891297 | C37: -877678 | D37: -11358713 | E37: -26629918
A38: Total Other Finance Cost | B38: -5627287 | C38: -6160782 | D38: -31797273 | E38: 5713920
A39: Interest Expense Non Operating | B39: 57680185 | C39: 57300560 | D39: 44038188 | E39: 42638140
A40: Interest Income Non Operating | B40: 54944195 | C40: 50262100 | D40: 882202 | E40: 21722142
A41: Operating Income | B41: 158407933 | C41: 248940591 | D41: 249887533 | E41: 190052442
A42: Operating Expense | B42: 97312078 | C42: 102376270 | D42: 107806264 | E42: 91794231
A43: Other Operating Expenses | B43: 4381619 | C43: 6678686 | D43: 8846581 | E43: 2315402
A44: Depreciation And Amortization In Income Statement | B44: 4159540 | C44: 4052035 | D44: 3941476 | E44: 4000610
A45: Depreciation Income Statement | B45: 4159540 | C45: 4052035 | D45: 3941476 | E45: 4000610
A46: Selling General And Administration | B46: 33000349 | C46: 32934066 | D46: 30132937 | E46: 28080243
A47: Selling And Marketing Expense | B47: 10129930 | C47: 9233950 | D47: 9503818 | E47: 8714411
A48: General And Administrative Expense | B48: 22870419 | C48: 23700116 | D48: 20629119 | E48: 19365832
... A53: Operating Revenue | B53: 868906517 | C53: 1290864982 | D53: 1525316550 | E53: 1321593256
A58: Its in rand

Sheet Price Targets
B1: Price (ZAc)
A2: current | B2: 425
A3: high | B3: 950
A4: low | B4: 950
A5: mean | B5: 950
A6: median | B6: 950

Sheet Recommendations
B1: period | C1: strongBuy | D1: buy | E1: hold | F1: sell | G1: strongSell
A2: 0 | B2: 0m | C2: 0 | D2: 0 | E2: 0 | F2: 0 | G2: 0
